<?xml version="1.0"?>
<!--
  Copyright 2015 Fadri Furrer, ASL, ETH Zurich, Switzerland
  Copyright 2015 Michael Burri, ASL, ETH Zurich, Switzerland
  Copyright 2015 Mina Kamel, ASL, ETH Zurich, Switzerland
  Copyright 2015 Janosch Nikolic, ASL, ETH Zurich, Switzerland
  Copyright 2015 Markus Achtelik, ASL, ETH Zurich, Switzerland

  Licensed under the Apache License, Version 2.0 (the "License");
  you may not use this file except in compliance with the License.
  You may obtain a copy of the License at

  http://www.apache.org/licenses/LICENSE-2.0

  Unless required by applicable law or agreed to in writing, software
  distributed under the License is distributed on an "AS IS" BASIS,
  WITHOUT WARRANTIES OR CONDITIONS OF ANY KIND, either express or implied.
  See the License for the specific language governing permissions and
  limitations under the License.
-->

<robot xmlns:xacro="http://ros.org/wiki/xacro">
  <!-- Main multirotor link -->
  <xacro:macro name="multirotor_base_macro"
    params="robot_namespace body_length body_width body_height mesh_file mesh_scale color">
    <link name="base_link">
      <visual>
        <origin xyz="0 0 0" rpy="0 0 0" />
        <geometry>
          <mesh filename="package://erle_models/meshes/meshes_drones/${mesh_file}"
            scale="${mesh_scale}" />
        </geometry>
      </visual>
   </link>
  </xacro:macro>

  <!-- Rotor joint and link -->
  <xacro:macro name="vertical_rotor"
    params="robot_namespace direction   parent  radius_rotor  motor_number  color mesh mesh_scale *origin">
    <joint name="rotor_${motor_number}_joint" type="continuous">
      <xacro:insert_block name="origin" />
      <axis xyz="0 0 1" />
      <parent link="${parent}" />
      <child link="rotor_${motor_number}" />
    </joint>
    <link name="rotor_${motor_number}">
      <visual>
        <geometry>
          <mesh filename="package://erle_models/meshes/meshes_drones/${mesh}_${direction}.dae"
            scale="${mesh_scale}" />
        </geometry>
      </visual>
    </link>
  </xacro:macro>
</robot>
